[
    {
        "type": "AttributeError",
        "args": [
            "'Pandas' object has no attribute 'targettablename'"
        ],
        "tb": "Traceback (most recent call last):\n  File \"C:\\Users\\Swathi\\Downloads\\Etl_New\\ETL_Framework\\common_utils\\audit.py\", line 152, in wrapper\n    source_count, insert_count, update_count = function(*args, **kwargs)\n                                               ^^^^^^^^^^^^^^^^^^^^^^^^^\n  File \"C:\\Users\\Swathi\\Downloads\\Etl_New\\ETL_Framework\\clicktoch\\db.py\", line 35, in click_to_ch\n    self._transfer_data(row, database_name, schema_name, table_name)\n  File \"C:\\Users\\Swathi\\Downloads\\Etl_New\\ETL_Framework\\clicktoch\\db.py\", line 148, in _transfer_data\n    logger.info(f'{row.targettablename.ljust(35)}{row_count:,} rows\\t' +\n                   ^^^^^^^^^^^^^^^^^^^\nAttributeError: 'Pandas' object has no attribute 'targettablename'\n",
        "timestamp": "2025-03-11T07:46:42.382285+00:00",
        "src": "clicktoch.db.click_to_ch",
        "obj_type": "Dimension",
        "sourceid": "region",
        "target_file": "d_region",
        "latestbatchid": 280
    }
]