Error occurred: (psycopg2.OperationalError) connection to server at "192.168.0.63", port 5432 failed: Connection timed out (0x0000274C/10060)
	Is the server running on that host and accepting TCP/IP connections?

(Background on this error at: https://sqlalche.me/e/20/e3q8)
Traceback (most recent call last):
  File "C:\Users\Swathi\AppData\Local\Programs\Python\Python312\Lib\site-packages\sqlalchemy\engine\base.py", line 146, in __init__
    self._dbapi_connection = engine.raw_connection()
                             ^^^^^^^^^^^^^^^^^^^^^^^
  File "C:\Users\Swathi\AppData\Local\Programs\Python\Python312\Lib\site-packages\sqlalchemy\engine\base.py", line 3302, in raw_connection
    return self.pool.connect()
           ^^^^^^^^^^^^^^^^^^^
  File "C:\Users\Swathi\AppData\Local\Programs\Python\Python312\Lib\site-packages\sqlalchemy\pool\base.py", line 449, in connect
    return _ConnectionFairy._checkout(self)
           ^^^^^^^^^^^^^^^^^^^^^^^^^^^^^^^^
  File "C:\Users\Swathi\AppData\Local\Programs\Python\Python312\Lib\site-packages\sqlalchemy\pool\base.py", line 1263, in _checkout
    fairy = _ConnectionRecord.checkout(pool)
            ^^^^^^^^^^^^^^^^^^^^^^^^^^^^^^^^
  File "C:\Users\Swathi\AppData\Local\Programs\Python\Python312\Lib\site-packages\sqlalchemy\pool\base.py", line 712, in checkout
    rec = pool._do_get()
          ^^^^^^^^^^^^^^
  File "C:\Users\Swathi\AppData\Local\Programs\Python\Python312\Lib\site-packages\sqlalchemy\pool\impl.py", line 179, in _do_get
    with util.safe_reraise():
         ^^^^^^^^^^^^^^^^^^^
  File "C:\Users\Swathi\AppData\Local\Programs\Python\Python312\Lib\site-packages\sqlalchemy\util\langhelpers.py", line 146, in __exit__
    raise exc_value.with_traceback(exc_tb)
  File "C:\Users\Swathi\AppData\Local\Programs\Python\Python312\Lib\site-packages\sqlalchemy\pool\impl.py", line 177, in _do_get
    return self._create_connection()
           ^^^^^^^^^^^^^^^^^^^^^^^^^
  File "C:\Users\Swathi\AppData\Local\Programs\Python\Python312\Lib\site-packages\sqlalchemy\pool\base.py", line 390, in _create_connection
    return _ConnectionRecord(self)
           ^^^^^^^^^^^^^^^^^^^^^^^
  File "C:\Users\Swathi\AppData\Local\Programs\Python\Python312\Lib\site-packages\sqlalchemy\pool\base.py", line 674, in __init__
    self.__connect()
  File "C:\Users\Swathi\AppData\Local\Programs\Python\Python312\Lib\site-packages\sqlalchemy\pool\base.py", line 900, in __connect
    with util.safe_reraise():
         ^^^^^^^^^^^^^^^^^^^
  File "C:\Users\Swathi\AppData\Local\Programs\Python\Python312\Lib\site-packages\sqlalchemy\util\langhelpers.py", line 146, in __exit__
    raise exc_value.with_traceback(exc_tb)
  File "C:\Users\Swathi\AppData\Local\Programs\Python\Python312\Lib\site-packages\sqlalchemy\pool\base.py", line 896, in __connect
    self.dbapi_connection = connection = pool._invoke_creator(self)
                                         ^^^^^^^^^^^^^^^^^^^^^^^^^^
  File "C:\Users\Swathi\AppData\Local\Programs\Python\Python312\Lib\site-packages\sqlalchemy\engine\create.py", line 643, in connect
    return dialect.connect(*cargs, **cparams)
           ^^^^^^^^^^^^^^^^^^^^^^^^^^^^^^^^^^
  File "C:\Users\Swathi\AppData\Local\Programs\Python\Python312\Lib\site-packages\sqlalchemy\engine\default.py", line 621, in connect
    return self.loaded_dbapi.connect(*cargs, **cparams)
           ^^^^^^^^^^^^^^^^^^^^^^^^^^^^^^^^^^^^^^^^^^^^
  File "C:\Users\Swathi\AppData\Local\Programs\Python\Python312\Lib\site-packages\psycopg2\__init__.py", line 122, in connect
    conn = _connect(dsn, connection_factory=connection_factory, **kwasync)
           ^^^^^^^^^^^^^^^^^^^^^^^^^^^^^^^^^^^^^^^^^^^^^^^^^^^^^^^^^^^^^^^
psycopg2.OperationalError: connection to server at "192.168.0.63", port 5432 failed: Connection timed out (0x0000274C/10060)
	Is the server running on that host and accepting TCP/IP connections?


The above exception was the direct cause of the following exception:

Traceback (most recent call last):
  File "C:\Users\Swathi\Downloads\Etl_New\ETL_Framework\silvertogold\__main__.py", line 66, in <module>
    main(cli_args)
  File "C:\Users\Swathi\Downloads\Etl_New\ETL_Framework\silvertogold\__main__.py", line 15, in main
    records = onesource.get_control_entries(
              ^^^^^^^^^^^^^^^^^^^^^^^^^^^^^^
  File "C:\Users\Swathi\Downloads\Etl_New\ETL_Framework\common_utils\onesource.py", line 22, in get_control_entries
    with self.engine.connect() as conn:
         ^^^^^^^^^^^^^^^^^^^^^
  File "C:\Users\Swathi\AppData\Local\Programs\Python\Python312\Lib\site-packages\sqlalchemy\engine\base.py", line 3278, in connect
    return self._connection_cls(self)
           ^^^^^^^^^^^^^^^^^^^^^^^^^^
  File "C:\Users\Swathi\AppData\Local\Programs\Python\Python312\Lib\site-packages\sqlalchemy\engine\base.py", line 148, in __init__
    Connection._handle_dbapi_exception_noconnection(
  File "C:\Users\Swathi\AppData\Local\Programs\Python\Python312\Lib\site-packages\sqlalchemy\engine\base.py", line 2442, in _handle_dbapi_exception_noconnection
    raise sqlalchemy_exception.with_traceback(exc_info[2]) from e
  File "C:\Users\Swathi\AppData\Local\Programs\Python\Python312\Lib\site-packages\sqlalchemy\engine\base.py", line 146, in __init__
    self._dbapi_connection = engine.raw_connection()
                             ^^^^^^^^^^^^^^^^^^^^^^^
  File "C:\Users\Swathi\AppData\Local\Programs\Python\Python312\Lib\site-packages\sqlalchemy\engine\base.py", line 3302, in raw_connection
    return self.pool.connect()
           ^^^^^^^^^^^^^^^^^^^
  File "C:\Users\Swathi\AppData\Local\Programs\Python\Python312\Lib\site-packages\sqlalchemy\pool\base.py", line 449, in connect
    return _ConnectionFairy._checkout(self)
           ^^^^^^^^^^^^^^^^^^^^^^^^^^^^^^^^
  File "C:\Users\Swathi\AppData\Local\Programs\Python\Python312\Lib\site-packages\sqlalchemy\pool\base.py", line 1263, in _checkout
    fairy = _ConnectionRecord.checkout(pool)
            ^^^^^^^^^^^^^^^^^^^^^^^^^^^^^^^^
  File "C:\Users\Swathi\AppData\Local\Programs\Python\Python312\Lib\site-packages\sqlalchemy\pool\base.py", line 712, in checkout
    rec = pool._do_get()
          ^^^^^^^^^^^^^^
  File "C:\Users\Swathi\AppData\Local\Programs\Python\Python312\Lib\site-packages\sqlalchemy\pool\impl.py", line 179, in _do_get
    with util.safe_reraise():
         ^^^^^^^^^^^^^^^^^^^
  File "C:\Users\Swathi\AppData\Local\Programs\Python\Python312\Lib\site-packages\sqlalchemy\util\langhelpers.py", line 146, in __exit__
    raise exc_value.with_traceback(exc_tb)
  File "C:\Users\Swathi\AppData\Local\Programs\Python\Python312\Lib\site-packages\sqlalchemy\pool\impl.py", line 177, in _do_get
    return self._create_connection()
           ^^^^^^^^^^^^^^^^^^^^^^^^^
  File "C:\Users\Swathi\AppData\Local\Programs\Python\Python312\Lib\site-packages\sqlalchemy\pool\base.py", line 390, in _create_connection
    return _ConnectionRecord(self)
           ^^^^^^^^^^^^^^^^^^^^^^^
  File "C:\Users\Swathi\AppData\Local\Programs\Python\Python312\Lib\site-packages\sqlalchemy\pool\base.py", line 674, in __init__
    self.__connect()
  File "C:\Users\Swathi\AppData\Local\Programs\Python\Python312\Lib\site-packages\sqlalchemy\pool\base.py", line 900, in __connect
    with util.safe_reraise():
         ^^^^^^^^^^^^^^^^^^^
  File "C:\Users\Swathi\AppData\Local\Programs\Python\Python312\Lib\site-packages\sqlalchemy\util\langhelpers.py", line 146, in __exit__
    raise exc_value.with_traceback(exc_tb)
  File "C:\Users\Swathi\AppData\Local\Programs\Python\Python312\Lib\site-packages\sqlalchemy\pool\base.py", line 896, in __connect
    self.dbapi_connection = connection = pool._invoke_creator(self)
                                         ^^^^^^^^^^^^^^^^^^^^^^^^^^
  File "C:\Users\Swathi\AppData\Local\Programs\Python\Python312\Lib\site-packages\sqlalchemy\engine\create.py", line 643, in connect
    return dialect.connect(*cargs, **cparams)
           ^^^^^^^^^^^^^^^^^^^^^^^^^^^^^^^^^^
  File "C:\Users\Swathi\AppData\Local\Programs\Python\Python312\Lib\site-packages\sqlalchemy\engine\default.py", line 621, in connect
    return self.loaded_dbapi.connect(*cargs, **cparams)
           ^^^^^^^^^^^^^^^^^^^^^^^^^^^^^^^^^^^^^^^^^^^^
  File "C:\Users\Swathi\AppData\Local\Programs\Python\Python312\Lib\site-packages\psycopg2\__init__.py", line 122, in connect
    conn = _connect(dsn, connection_factory=connection_factory, **kwasync)
           ^^^^^^^^^^^^^^^^^^^^^^^^^^^^^^^^^^^^^^^^^^^^^^^^^^^^^^^^^^^^^^^
sqlalchemy.exc.OperationalError: (psycopg2.OperationalError) connection to server at "192.168.0.63", port 5432 failed: Connection timed out (0x0000274C/10060)
	Is the server running on that host and accepting TCP/IP connections?

(Background on this error at: https://sqlalche.me/e/20/e3q8)
